Workbook
Name IQ_CH: 110000
Name IQ_CQ: 5000
Name IQ_CY: 10000
Name IQ_DAILY: 500000
Name IQ_FH: 100000
Name IQ_FQ: 500
Name IQ_FY: 1000
Name IQ_LTM: 2000
Name IQ_MONTH: 15000
Name IQ_NTM: 6000
Name IQ_WEEK: 50000
Name IQ_YTD: 3000

Sheet Cover Page & Directory
B35: 1 | C35: GRI & SASB Index | D35: 5 | E35: Health & Safety | F35: 8 | G35: Materials,Tailings and Waste
B36: 2 | C36: Perfomance Summary | D36: 6 | E36: Energy & Emissions | F36: 9 | G36: Environmental Stewardship
B37: 3 | C37: Workforce | D37: 7 | E37: Water Management | F37: 10 | G37: Communities & Indigenous Peoples
B38: 4 | C38: Economic Performance & Contributions

Sheet GRI & SASB Index
A7: Topic | B7: Indicator Number | C7: Description | D7: Reference | E7: Comment/Response | F7: Workbook Directory
A8: Organizational Profile | B8: GRI 102-01 | C8: Name of the organization | E8: Agnico Eagle Mines Limited
A9: Organizational Profile | B9: GRI 102-02 | C9: Activities, brands, products, and services | D9: Agnico Eagle at-a-glance 2019 Sustainable Development Report (p. 2)
A10: Organizational Profile | B10: GRI 102-03 | C10: Location of headquarters | E10: Toronto, Ontario (Canada)
A11: Organizational Profile | B11: GRI 102-04 | C11: Location of operations | D11: Agnico Eagle at-a-glance 2019 Sustainable Development Report (p. 2)
A12: Organizational Profile | B12: GRI 102-05 | C12: Ownership and legal form | D12: 2019 Annual Report
A13: Organizational Profile | B13: GRI 102-06 | C13: Markets served | D13: 2019 Annual Report
A14: Organizational Profile | B14: GRI 102-07 | C14: Scale of the organization | D14: Agnico Eagle at-a-glance 2019 Sustainable Development Report (p. 2) 2019 Annual Report
A15: Organizational Profile | B15: GRI 102-08 | C15: Information on employees and other workers | D15: Our People 2019 Sustainable Development Report (p. 44) 2019 Sustainability Performance Data | E15: Workforce data is compiled using the number of employees as of year-end. Workforce data includes permanent, temporary and on-call employees unless otherwise stated. | F15: Go to data
A16: Organizational Profile | B16: GRI 102-09 | C16: Supply chain | D16: 2019 Annual Report
A17: Organizational Profile | B17: GRI 102-10 | C17: Significant changes to the organization and its supply chain | D17: 2019 Annual Report
A18: Organizational Profile | B18: GRI 102-11 | C18: Precautionary Principle or approach | D18: Our Approach 2019 Sustainable Development Report (p. 6)
A19: Organizational Profile | B19: GRI 102-12 | C19: External initiatives | D19: Our Approach 2019 Sustainable Development Report (p. 6)
A20: Organizational Profile | B20: GRI 102-13 | C20: Membership of associations | D20: Our Approach 2019 Sustainable Development Report (p. 6)
A21: Strategy | B21: GRI 102-14 | C21: Statement from senior decision-maker | D21: Message from the CEO Message from the Senior-Vice President 2019 Sustainable Development Report (p. 4-5)
A22: Strategy | B22: GRI 102-15 | C22: Key impacts, risks, and opportunities | D22: 2019 Performance Highlights Our Objectives and Targets 2019 Sustainable Development Report (p. 8-9)
A23: Ethics and integrity | B23: GRI 102-16 | C23: Values, principles, standards, and norms of behavior | D23: Governance 2019 Sustainable Development Report (p. 15)
A24: Ethics and integrity | B24: GRI 102-17 | C24: Mechanisms for advice and concerns about ethics | D24: Governance 2019 Sustainable Development Report (p. 15)
A25: Governance | B25: GRI 102-18 | C25: Governance structure | D25: Management Proxy Circular 2020
A26: Governance | B26: GRI 102-20 | C26: Executive-level responsibility for economic, environmental, and social topics | D26: Governance 2019 Sustainable Development Report (p. 15)
A27: Governance | B27: GRI 102-21 | C27: Consulting stakeholders on economic, environmental, and social topics | D27: Stakeholder Engagement 2019 Sustainable Development Report (p. 10)
... A36: Governance | B36: GRI 102-31 | C36: Review of economic, environmental, and social topics | D36: Governance 2019 Sustainable Development Report (p.15)
A37: Governance | B37: GRI 102-32 | C37: Highest governance body’s role in sustainability reporting | E37: Our executive leadership team, including the CEO and SVP Sustainability, review and approve this report prior to publication
A38: Governance | B38: GRI 102-33 | C38: Communicating critical concerns | D38: Governance 2019 Sustainable Development Report (p. 15)
A39: Governance | B39: GRI 102-34 | C39: Nature and total number of critical concerns | D39: Governance 2019 Sustainable Development Report (p. 15)
A40: Governance | B40: GRI 102-35 | C40: Remuneration policies | D40: Management Proxy Circular 2020
A41: Governance | B41: GRI 102-36 | C41: Process for determining remuneration | D41: Management Proxy Circular 2020
A42: Governance | B42: GRI 102-37 | C42: Stakeholders’ involvement in remuneration | D42: Management Proxy Circular 2020
A43: Stakeholder Engagement | B43: GRI 102-40 | C43: List of stakeholder groups | D43: Stakeholder Engagement 2019 Sustainable Development Report (p. 10)
A44: Stakeholder Engagement | B44: GRI 102-42 | C44: Identifying and selecting stakeholders | D44: Stakeholder Engagement 2019 Sustainable Development Report (p. 10)
A45: Stakeholder Engagement | B45: GRI 102-43 | C45: Approach to stakeholder engagement | D45: Stakeholder Engagement Social and Economic Development 2019 Sustainable Development Report (p. 10, 54)
A46: Stakeholder Engagement | B46: GRI 102-44 | C46: Key topics and concerns raised | D46: Stakeholder Engagement Social and Economic Development 2019 Sustainable Development Report (p. 10, 54)
A47: Reporting Practice | B47: GRI 102-45 | C47: Entities included in the consolidated financial statements | D47: 2019 Annual Report
A48: Reporting Practice | B48: GRI 102-46 | C48: Defining report content and topic Boundaries | D48: Sustainability Materiality Assessment 2019 Sustainable Development Report (p. 12)
A49: Reporting Practice | B49: GRI 102-47 | C49: List of material topics | D49: Sustainability Materiality Assessment 2019 Sustainable Development Report (p. 12)
A50: Reporting Practice | B50: GRI 102-48 | C50: Restatements of information | D50: Cover Page & Directory 2019 Sustainable Development Reports (p.12) | F50: Go to data
A51: Reporting Practice | B51: GRI 102-49 | C51: Changes in reporting | D51: About This Report 2019 Sustainable Development Report (p. 1)
A52: Reporting Practice | B52: GRI 102-50 | C52: Reporting period | E52: January 1 - December 31, 2019 (unless otherwise stated)
A53: Reporting Practice | B53: GRI 102-51 | C53: Date of most recent report | E53: April, 2019
A54: Reporting Practice | B54: GRI 102-52 | C54: Reporting cycle | E54: Annual
...

Sheet Performance Summary
C6: 2019 | D6: 2018 | E6: 2017 | F6: 2016 | G6: 2015
A7: Operations
A8: GRI 301-1 SASB EM-MM-000.A | B8: Production
B9: Total Ore processed (tonnes) | C9: 19565207 | D9: 20109520 | E9: 21222813 | F9: 21176764 | G9: 20369073
B10: Total Gold (Oz) | C10: 1447547.4 | D10: 1278069 | E10: 1396287.8 | F10: 1370373 | G10: 1385531
A11: Health, Safety & Wellness
A12: Global Safety Performance
A13: GRI 403-09 SASB EM-MM-320a.1 | B13: Person-hours worked | C13: 20384101 | D13: 20227598 | E13: 18110348 | F13: 16702903 | G13: 14995802
B14: Number of fatalities | C14: 0 | D14: 0 | E14: 0 | F14: 1 | G14: 0
B15: Frequency (combined lost-time accidents and restricted workcases per 200,000 person hours worked) | C15: 0.99 | D15: 1.28 | E15: 0.91 | F15: 0.97 | G15: 1.23
A16: Environmental Stewardship
A17: Energy & Climate Change
A18: GRI 302-1 SASB EM-MM-130a.1 | B18: Energy Consumption
B19: Total Electricity (GWh) | C19: 1201.7056 | D19: 1114.9847 | E19: 1114.2669 | F19: 1091.6555 | G19: 1049.4655
B20: % Renewable Electricity | C20: 0.68 | D20: 0.75 | E20: 0.74 | F20: 0.76 | G20: 0.75
B21: Total Energy Consumption (GJ) | C21: 9342624.4 | D21: 8183269.2 | E21: 8165242 | F21: 7644178 | G21: 8578403
A22: GRI 302-3 | B22: Energy Intensity
B23: Electricity Intensity (per tonne of ore processed) (GWh/t) | C23: =C19/C9*1000000 -> 61.420542 | D23: =D19/D9*1000000 -> 55.445617 | E23: =E19/E9*1000000 -> 52.503263 | F23: =F19/F9*1000000 -> 51.549683 | G23: =G19/G9*1000000 -> 51.522499
B24: Energy Intensity (per tonne of ore processed) (GJ/t) | C24: =C21/C9 -> 0.47751218 | D24: =D21/D9 -> 0.40693509 | E24: =E21/E9 -> 0.38473891 | F24: =F21/F9 -> 0.36097006 | G24: =G21/G9 -> 0.42114842
A25: GRI 305-1 SASB EM-MM-110a.1 | B25: Direct (Scope 1) GHG Emissions (tonnes of CO2E) | C25: 442418.45 | D25: 332437.4 | E25: 335519 | F25: 325922 | G25: 337190
A26: GRI 305-2 | B26: Indirect (Scope 2) GHG Emissions (tonnes of CO2E) | C26: 78413.218 | D26: 78908.841 | E26: 79136 | F26: 74488 | G26: 70281
A27: GRI 305-4 | B27: Total (Scope 1 + 2) GHG Emissions (tonnes of CO2E) | C27: =C25+C26 -> 520831.67 | D27: =D25+D26 -> 411346.24 | E27: =SUM(E25+E26) -> 414655 | F27: =SUM(F25+F26) -> 400410 | G27: =SUM(G25+G26) -> 407471
B28: GHG Intensity (tonnes of CO2 eq. per tonne of ore processed) | C28: =C27/C9 -> 0.0266203 | D28: 0.0205 | E28: 0.0195 | F28: 0.0189 | G28: 0.020004396
A29: GRI 305-7 SASB EM-MM-120a.1 | B29: Air Emissions
B30: Noxides (Nox) (tonnes) | C30: 12068.291 | D30: 8889 | E30: 9075 | F30: 8788 | G30: 9081
B31: Sulfur oxides (Sox) (tonnes) | C31: 791.42622 | D31: 582 | E31: 606 | F31: 584 | G31: 607
A32: Water Management
A33: GRI 303-3 SASB EM-MM-140a.1 | B33: Water Withdrawal
B34: Total Water Withdrawn (m3) | C34: 9532210.4 | D34: 7339774.6 | E34: =SUM(E35:E38) -> 6449267.3 | F34: 6115542 | G34: =SUM(G35:G38) -> 6650639.3
B35: Surface water (m3) | C35: 8154295.9 | D35: 6165976.9 | E35: 5458138 | F35: 4940103 | G35: 5645775
B36: Groundwater (m3) | C36: 1366615.5 | D36: 1172259.7 | E36: 988805 | F36: 1172350 | G36: 1001818
B37: Third-party water (m3) | C37: 11299 | D37: 1538 | E37: 2324 | F37: 3088 | G37: 3046
B38: Water Withdrawn Intensity (m3 of water per tonned of ore processed) | C38: =C34/C9 -> 0.48720213 | D38: 0.37 | E38: 0.3 | F38: 0.29 | G38: 0.32
A39: GRI 303-4 | B39: Water Discharged
B40: Total Water Discharged (m3) | C40: 17407896 | D40: 9771778.4 | E40: 11855280 | F40: 12066968 | G40: 9843008
A41: GRI 303-5 SASB EM-MM-140a.1 | B41: Water Consumption
B42: Total Water Used (m3) | C42: 24950028 | D42: 20206694 | E42: 19865414 | F42: 18182510 | G42: 20059203
B43: Total Water Recycled (%) | C43: 0.62 | D43: 0.64 | E43: 0.71 | F43: 0.69 | G43: 0.67
A44: Tailings & Waste Management
A45: GRI 306-2 SASB EM-MM-150a.1 | B45: Mineral Wastes
...

Sheet Workforce
A7: Global Workforce by Employment Type, Contract, Gender and Region
A8: GRI 102-08 SASB EM-MM-000.B | B8: Global AEM | C8: Laronde | D8: Goldex | E8: Kittila | F8: Pinos Altos | G8: La India | H8: Meadowbank | I8: Meliadine | J8: Exploration Canada & USA | K8: Exploration Europe Sweden | L8: Exploration Europe Finland | M8: Exploration Mexico | N8: Administration (head office) | O8: Administration Regional CSD
A9: Total Contractors | B9: 2922 | C9: 429 | D9: 166 | E9: 633 | F9: 211 | G9: 60 | H9: 616 | I9: 583 | J9: 82 | K9: 1 | L9: 0 | M9: 141 | N9: 0 | O9: 0
A10: Total Agnico Employees | B10: 5852 | C10: 977 | D10: 429 | E10: 472 | F10: 1427 | G10: 399 | H10: 1033 | I10: 611 | J10: 78 | K10: 10 | L10: 7 | M10: 62 | N10: 163 | O10: 184
A11: Total Employees Male | B11: 4937 | C11: 882 | D11: 385 | E11: 408 | F11: 1220 | G11: 342 | H11: 820 | I11: 536 | J11: 59 | K11: 9 | L11: 6 | M11: 52 | N11: 116 | O11: 102
A12: Total Employees Female | B12: 915 | C12: 95 | D12: 44 | E12: 64 | F12: 207 | G12: 57 | H12: 213 | I12: 75 | J12: 19 | K12: 1 | L12: 1 | M12: 10 | N12: 47 | O12: 82
A13: Total Agnico Permanent | B13: 5390 | C13: 936 | D13: 411 | E13: 450 | F13: 1380 | G13: 394 | H13: 802 | I13: 579 | J13: 53 | K13: 10 | L13: 7 | M13: 59 | N13: 149 | O13: 160
A14: Permanent Male | B14: 4637 | C14: 858 | D14: 374 | E14: 392 | F14: 1187 | G14: 338 | H14: 660 | I14: 516 | J14: 40 | K14: 9 | L14: 6 | M14: 52 | N14: 111 | O14: 94
A15: Permanent Female | B15: 753 | C15: 78 | D15: 37 | E15: 58 | F15: 193 | G15: 56 | H15: 142 | I15: 63 | J15: 13 | K15: 1 | L15: 1 | M15: 7 | N15: 38 | O15: 66
A16: Total Agnico Temporary¹ | B16: 385 | C16: 41 | D16: 18 | E16: 22 | F16: 47 | G16: 5 | H16: 155 | I16: 31 | J16: 25 | K16: 0 | L16: 0 | M16: 3 | N16: 14 | O16: 24
A17: Temporary Male | B17: 255 | C17: 24 | D17: 11 | E17: 16 | F17: 33 | G17: 4 | H17: 115 | I17: 20 | J17: 19 | K17: 0 | L17: 0 | M17: 0 | N17: 5 | O17: 8
A18: Temporary Female | B18: 130 | C18: 17 | D18: 7 | E18: 6 | F18: 14 | G18: 1 | H18: 40 | I18: 11 | J18: 6 | K18: 0 | L18: 0 | M18: 3 | N18: 9 | O18: 16
A19: Total Agnico On-Call | B19: 77 | C19: - | D19: - | E19: - | F19: - | G19: - | H19: 76 | I19: 1 | J19: - | K19: - | L19: - | M19: - | N19: - | O19: -
A20: Temporary Male | B20: 45 | C20: - | D20: - | E20: - | F20: - | G20: - | H20: 45 | I20: - | J20: - | K20: - | L20: - | M20: - | N20: - | O20: -
A21: Temporary Female | B21: 32 | C21: - | D21: - | E21: - | F21: - | G21: - | H21: 31 | I21: 1 | J21: - | K21: - | L21: - | M21: - | N21: - | O21: -
A22: Percentage Contractors | B22: =B9/B23 -> 0.33302941 | C22: =C9/C23 -> 0.30512091 | D22: =D9/D23 -> 0.2789916 | E22: =E9/E23 -> 0.57285068 | F22: =F9/F23 -> 0.12881563 | G22: =G9/G23 -> 0.13071895 | H22: =H9/H23 -> 0.37355973 | I22: =I9/I23 -> 0.48827471 | ... O22: =O9/O23 -> 0
A23: Total Workforce | B23: 8774 | C23: 1406 | D23: 595 | E23: 1105 | F23: 1638 | G23: 459 | H23: 1649 | I23: 1194 | J23: 160 | K23: 11 | L23: 7 | M23: 203 | N23: 163 | O23: 184
A24: ¹ Temporary employees includes students
A26: New employee hires by age group, gender, and region
A27: 401-01 | B27: Global AEM | C27: Laronde | D27: Goldex | E27: Kittila | F27: Pinos Altos | G27: La India | H27: Meadowbank | I27: Meliadine | J27: Exploration Canada & USA | K27: Exploration Europe Sweden | L27: Exploration Europe Finland | M27: Exploration Mexico | N27: Administration (head office) | O27: Administration Regional CSD
A28: Total Female New Hires | B28: 260 | C28: 29 | D28: 9 | E28: 15 | F28: 54 | G28: 14 | H28: 67 | I28: 30 | J28: 6 | K28: 1 | L28: 0 | M28: 2 | N28: 14 | O28: 19
A29: Female under 30 years | B29: 163 | C29: 25 | D29: 8 | E29: 13 | F29: 34 | G29: 12 | H29: 27 | I29: 16 | J29: 6 | K29: 1 | L29: 0 | M29: 2 | N29: 5 | O29: 14
A30: Female 30-50 years | B30: 81 | C30: 4 | D30: 1 | E30: 2 | F30: 16 | G30: 2 | H30: 34 | I30: 13 | J30: 0 | K30: 0 | L30: 0 | M30: 0 | N30: 5 | O30: 4
A31: Female over 50 years | B31: 16 | C31: 0 | D31: 0 | E31: 0 | F31: 4 | G31: 0 | H31: 6 | I31: 1 | J31: 0 | K31: 0 | L31: 0 | M31: 0 | N31: 4 | O31: 1
A32: Total Male New Hires | B32: 959 | C32: 67 | D32: 42 | E32: 48 | F32: 238 | G32: 126 | H32: 240 | I32: 160 | J32: 3 | K32: 2 | L32: 0 | M32: 0 | N32: 17 | O32: 16
A33: Male under 30 years | B33: 483 | C33: 52 | D33: 36 | E33: 30 | F33: 152 | G33: 60 | H33: 74 | I33: 54 | J33: 2 | K33: 2 | L33: 0 | M33: 0 | N33: 7 | O33: 14
A34: Male 30-50 years | B34: 388 | C34: 13 | D34: 6 | E34: 14 | F34: 82 | G34: 64 | H34: 121 | I34: 80 | J34: 1 | K34: 0 | L34: 0 | M34: 0 | N34: 6 | O34: 1
A35: Male over 50 years | B35: 88 | C35: 2 | D35: 0 | E35: 4 | F35: 4 | G35: 2 | H35: 45 | I35: 26 | J35: 0 | K35: 0 | L35: 0 | M35: 0 | N35: 4 | O35: 1
A36: Total New Hires | B36: 1219 | C36: 96 | D36: 51 | E36: 63 | F36: 292 | G36: 140 | H36: 307 | I36: 190 | J36: 9 | K36: 3 | L36: 0 | M36: 2 | N36: 31 | O36: 35
A38: New employee hire rate¹ by gender, and region
A39: 401-01 | B39: Global AEM | C39: Laronde | D39: Goldex | E39: Kittila | F39: Pinos Altos | G39: La India | H39: Meadowbank | I39: Meliadine | J39: Exploration Canada & USA | K39: Exploration Europe Sweden | L39: Exploration Europe Finland | M39: Exploration Mexico | N39: Administration (head office) | O39: Administration Regional CSD
A40: Total Female New Hire Rate | B40: 0.28776978 | C40: 0.2974359 | D40: 0.2 | E40: 0.22727273 | F40: 0.25352113 | G40: 0.24137931 | H40: 0.32682927 | I40: 0.46875 | J40: 0.3 | K40: 1 | L40: 0 | M40: 0.2 | N40: 0.30434783 | O40: 0.24675325
A41: Total Male New Hire Rate | B41: 0.19760973 | C41: 0.074944072 | D41: 0.10606061 | E41: 0.11483254 | F41: 0.19620775 | G41: 0.36734694 | H41: 0.31578947 | I41: 0.32854209 | J41: 0.050847458 | K41: 0.22222222 | L41: 0 | M41: 0 | N41: 0.1440678 | O41: 0.16326531
A42: Total New Hire Rate | B42: 0.21176062 | C42: 0.096822995 | D42: 0.11564626 | E42: 0.13016529 | F42: 0.20476858 | G42: 0.34912718 | H42: 0.31813472 | I42: 0.34482759 | J42: 0.11392405 | K42: 0.3 | L42: 0 | M42: 0.031746032 | N42: 0.18902439 | O42: 0.2
A43: ¹ New hire rate is calculated as the number of new hires for the year over the average number of employees for the year
A45: Permanent Employee Turnover¹ by age group, gender, and region
A46: 401-01 | B46: Global AEM | C46: Laronde | D46: Goldex | E46: Kittila | F46: Pinos Altos | G46: La India | H46: Meadowbank | I46: Meliadine | J46: Exploration Canada & USA | K46: Exploration Europe Sweden | L46: Exploration Europe Finland | M46: Exploration Mexico | N46: Administration (head office) | O46: Administration Regional CSD
A47: Total Female Turnover | B47: 108 | C47: 3 | D47: 1 | E47: 6 | F47: 36 | G47: 13 | H47: 33 | I47: 5 | J47: 1 | K47: 0 | L47: 0 | M47: 0 | N47: 7 | O47: 3
A48: Female under 30 years | B48: 48 | C48: 3 | D48: 1 | E48: 5 | F48: 12 | G48: 8 | H48: 13 | I48: 2 | J48: 0 | K48: 0 | L48: 0 | M48: 0 | N48: 3 | O48: 1
A49: Female 30-50 years | B49: 52 | C49: 0 | D49: 0 | E49: 1 | F49: 22 | G49: 5 | H49: 15 | I49: 3 | J49: 1 | K49: 0 | L49: 0 | M49: 0 | N49: 4 | O49: 1
...

Sheet Economic Performance
A7: Ratios of standard entry level wage by gender compared to local minimum wage
A8: GRI 202-1 | C8: Laronde | D8: Goldex | E8: Kittila | F8: Pinos Altos | G8: La India | H8: Meadowbank | I8: Meliadine
A9: Local Minimum Wage in Local Currency | C9: 12.5 | D9: 12.5 | E9: 11.82 | F9: 123.22 | G9: 123.22 | H9: 13 | I9: 13
A10: Ratio of Female Entry Level Wage to Local Minimum Wage | C10: 2.7:1 | D10: 2.8:1 | E10: 1:1 | F10: 1.8:1 | G10: 1.7:1 | H10: 1.8:1 | I10: 1.8:1
A11: Ratio of Male Entry Level Wage to Local Minimum Wage | C11: 2.7:1 | D11: 2.8:1 | E11: 1:1 | F11: 1.8:1 | G11: 1.7:1 | H11: 1.8:1 | I11: 1.8:1
A13: Proportion of senior management¹ hired from the local² community
A14: GRI 202-1 | C14: Laronde | D14: Goldex | E14: Kittila | F14: Pinos Altos | G14: La India | H14: Meadowbank | I14: Meliadine
A15: % Senior management positions filled by locals | C15: 1 | D15: 0.94 | E15: 0.69 | F15: 0 | G15: 0.1 | H15: 0 | I15: 0
A16: ¹ Senior management is defined by their compensation band, which is determined by job responsibilities
A17: ²Local is defined as employees who are living and/or working in the region in which the division operates.
A19: Proportion of spending on local¹ suppliers
A20: GRI 202-1 | B20: Global AEM | C20: Laronde² | D20: Goldex | E20: Kittila | F20: Pinos Altos | G20: La India | H20: Meadowbank | I20: Meliadine
A21: % of spending on local suppliers | B21: 0.5886305 | C21: =C22/C23 -> 0.72545591 | D21: =D22/D23 -> 0.66997137 | E21: =E22/E23 -> 0.24062145 | F21: =F22/F23 -> 0.96803472 | G21: =G22/G23 -> 0.61406675 | H21: =H22/H23 -> 0.6453284 | I21: =I22/I23 -> 0.5268529
A22: Total purchases from local region (USD) | B22: 8.6547147e+08 | C22: 1.7070146e+08 | D22: 54183300 | E22: 71108623 | F22: 1.4943058e+08 | G22: 30555195 | H22: 2.4331909e+08 | I22: 1.4617324e+08
A23: Total purchases (USD) | B23: 1.4703137e+09 | C23: 2.3530232e+08 | D23: 80874053 | E23: 2.9552072e+08 | F23: 1.5436489e+08 | G23: 49758751 | H23: 3.7704692e+08 | I23: 2.7744601e+08
A24: ¹ Local is defined as the region in which the division operates
A25: ² Purchases for the decommissioned Lapa operations are included with Laronde
A27: Direct economic value generated and distributed (USD)¹
A28: GRI 201-1 | B28: Global AEM | C28: Canada | D28: Finland | E28: Mexico
A29: Revenues | B29: 2494892000
A30: Employee wages and benefits | B30: 636800000
A31: Payments to Government ² | B31: 58585266 | C31: 38943141 | D31: 2733295 | E31: 16908830
A32: Community Investments | B32: 7436284.5
A33: ¹ Values are reported on a accrual basis in USD unless otherwise noted. All values except community investments include Canadian Malarctic as per Agnico Eagle's annual report.
A34: ² Tax balances have been prepared on a cash basis for what was actually paid to the government and does not tie to the expense on the income statement.

Sheet Health & Safety
A7: Work-Related Injuries¹
A8: GRI 403-10 SASB EM-MM-320a.1 | B8: Global AEM | C8: Laronde | D8: Goldex | E8: Kittila | F8: Pinos Altos | G8: La India | H8: Meadowbank | I8: Meliadine | J8: Exploration | K8: Administration (head office) | L8: Administration Regional CSD
A9: Person Hours Worked | B9: 20384101 | C9: 2642009 | D9: 1141603 | E9: 2156507 | F9: 4873830 | G9: 1902727 | H9: 3445277 | I9: 2444088 | J9: 1098733 | K9: 321645 | L9: 357682
A10: Light Duty Assignments Restricted work | B10: 48 | C10: 5 | D10: 2 | E10: 3 | F10: 1 | G10: 1 | H10: 20 | I10: 12 | J10: 4 | K10: 0 | L10: 0
A11: Lost Time Accidents | B11: 53 | C11: 6 | D11: 2 | E11: 8 | F11: 2 | G11: 0 | H11: 25 | I11: 8 | J11: 2 | K11: 0 | L11: 0
A12: Combined lost-time accident and restricted work frequency (combined lost-time accidents and restricted workcases per 200,000 person hours worked) | B12: 0.99 | C12: 0.83 | D12: 0.7 | E12: 1.02 | F12: 0.12 | G12: 0.11 | H12: 2.61 | I12: 1.64 | J12: 1.09 | K12: 0 | L12: 0
A13: Combined lost-time accident and restricted work frequency (combined lost-time accidents and restricted workcases per 1,000,000 person hours worked) | B13: 4.954842 | C13: 4.1634983 | D13: 3.503845 | E13: 5.1008413 | F13: 0.61553234 | G13: 0.52556147 | H13: 13.061359 | I13: 8.1830114 | J13: 5.4608353 | K13: 0 | L13: 0
A14: Medical Acts | B14: 108 | C14: 26 | D14: 19 | E14: 7 | F14: 1 | G14: 8 | H14: 14 | I14: 30 | J14: 3 | K14: 0 | L14: 0
A15: Fatalities | B15: 0 | C15: 0 | D15: 0 | E15: 0 | F15: 0 | G15: 0 | H15: 0 | I15: 0 | J15: 0 | K15: 0 | L15: 0
A17: ¹ Work related injuries include employees and contractors

Sheet Energy & Emissions
A7: Energy Consumption Within The Organization
A8: GRI 302-1 | B8: Global AEM | C8: Laronde | D8: Goldex | E8: Kittila | F8: Pinos Altos | G8: La India | H8: Meadowbank | I8: Meliadine
A9: Fuel Consumption
A10: Diesel (L) | B10: 1.4663275e+08 | C10: 7312656.2 | D10: 2666561 | E10: 3361055.6 | F10: 12550003 | G10: 15246392 | H10: 67587162 | I10: 37908915
A11: Natural Gas Consumption (m³) | B11: 10788530 | C11: 8316170 | D11: 2472360 | E11: - | F11: - | G11: - | H11: - | I11: -
A12: Light Fuel & Gasoline Consumption (L) | B12: =SUM(C12:I12) -> 1182011.3 | C12: 120001.3 | D12: 35162 | F12: 503686.6 | G12: 354192.63 | H12: 137150 | I12: 31818.8
A13: Aviation Fuel (L) | B13: =SUM(C13:I13) -> 1863132 | C13: - | D13: - | E13: - | F13: 48000 | G13: 38200 | H13: 1724705 | I13: 52227
A14: Propane Gas Consumption (L) | B14: =SUM(C14:I14) -> 7103.44 | C14: - | E14: 206.44 | F14: - | G14: - | H14: 6897 | I14: -
A15: Liquid Petroleum Gas (LPG) (L) | B15: =SUM(C15:I15) -> 55902.252 | C15: - | D15: - | E15: - | F15: 652.2523 | G15: 55250 | H15: - | I15: -
A16: Explosives (tonnes) | B16: =SUM(C16:I16) -> 22039.644 | C16: 1707.366 | D16: 716.67 | E16: 2713.8 | F16: 5701.2221 | G16: 3878.9 | H16: 5284.986 | I16: 2036.7
A17: Total Electricity Consumption (kWh) | B17: =SUM(C17:I17) -> 1.2017056e+09 | C17: =SUM(C18:C20) -> 4.3034337e+08 | D17: =SUM(D18:D20) -> 1.6436984e+08 | E17: =SUM(E18:E20) -> 225162470 | F17: =SUM(F18:F20) -> 1.3281661e+08 | G17: =SUM(G18:G20) -> 20943361 | H17: =SUM(H18:H20) -> 129386510 | I17: =SUM(I18:I20) -> 98683431
A18: Renewable Electricity Purchased from Grid (kWh) | B18: =SUM(C18:I18) -> 8.1987568e+08 | C18: 4.3034337e+08 | D18: 1.6436984e+08 | E18: 225162470 | F18: - | G18: - | H18: - | I18: -
A19: Non-Renewable Electricity Purchased from Grid (kWh) | B19: =SUM(C19:I19) -> 1.3251236e+08 | C19: - | D19: - | E19: - | F19: 1.3251236e+08 | G19: - | H19: - | I19: -
A20: Non-Renewable Electricity Generated On-site (kWh) | B20: 2.4931756e+08 | C20: - | D20: - | E20: - | F20: 304254.41 | G20: 20943361 | H20: 129386510 | I20: 98683431
A21: Total Energy Consumption (GJ) | B21: =SUM(C21:I21) -> 9342624.4 | C21: 2145859.9 | D21: 788138.69 | E21: 883520.26 | F21: 981567.76 | G21: 604782.79 | H21: 2677191.2 | I21: 1261563.8
A23: Energy Intensity
A24: GRI 302-3 | B24: Global AEM | C24: Laronde | D24: Goldex | E24: Kittila | F24: Pinos Altos | G24: La India | H24: Meadowbank | I24: Meliadine
A25: Electricity Intensity (per tonne of ore processed) (GWh/t) | B25: 61.420542 | C25: 147.03773 | D25: 59.029787 | E25: 141.53135 | F25: 43.212643 | G25: 3.8766664 | H25: 47.044405 | I25: 95.185718
A26: Energy Intensity (per tonne of ore processed) (GJ/t) | B26: 0.47751218 | C26: 0.73318747 | D26: 0.28304255 | E26: 0.55535817 | F26: 0.31935867 | G26: 0.11194675 | H26: 0.97341576 | I26: 1.2168492
A28: Greenhouse Gas (GHG) Emissions
A29: GRI 305-1. 305-2, 305-4 SASB EM-MM-110a.1 | B29: Global AEM | C29: Laronde | D29: Goldex | E29: Kittila | F29: Pinos Altos | G29: La India | H29: Meadowbank | I29: Meliadine
A30: Direct GHG Produced (Scope 1 (CO2e)) | B30: 442418.45 | C30: 38305.597 | D30: 13589.955 | E30: 9546.2913 | F30: 36484.972 | G30: 43769.173 | H30: 192668.07 | I30: 108054.39
A31: Indirect GHG Produced (Scope 2 (CO2e)) | B31: 78413.218 | C31: 860.68674 | D31: 1495.7656 | E31: 13802.459 | F31: 62254.307 | G31: - | H31: - | I31: -
A32: Total GHG Produced (CO2e) | B32: 520831.67 | C32: 39166.284 | D32: 15085.72 | E32: 23348.751 | F32: 98739.279 | G32: 43769.173 | H32: 192668.07 | I32: 108054.39
A33: GHG Intensity (Total GHG/tonne ore treated) | B33: 0.0266203 | C33: 0.013382154 | D33: 0.0054177022 | E33: 0.014676426 | F33: 0.032125387 | G33: 0.0081017791 | H33: 0.07005332 | I33: 0.10422454
A34: Scope 1 emissions covered under an emissions-limiting regulation or program | B34: =SUM(C30:E30,H30:I30)/B30 -> 0.81860127 | C34: Yes | D34: Yes | E34: Yes | F34: No | G34: No | H34: Yes | I34: Yes
A36: Nitrogen oxides (Nox), sulfur oxides (Sox), and other significant air emissions
A37: GRI 305-7 SASB EM-MM-120a.1 | B37: Global AEM | C37: Laronde | D37: Goldex | E37: Kittila | F37: Pinos Altos | G37: La India | H37: Meadowbank | I37: Meliadine
A38: Noxides (Nox) (tonnes) | B38: 12068.291 | C38: 613.51131 | D38: 222.58834 | E38: 274.37621 | F38: 1039.3833 | G38: 1255.2014 | H38: 5566.3465 | I38: 3096.8841
A39: Sulfur oxides (Sox) (tonnes) | B39: 791.42622 | C39: 39.503803 | D39: 14.387656 | E39: 18.04288 | F39: 68.137829 | G39: 82.391095 | H39: 365.34471 | I39: 203.61825

Sheet Water Management
A7: Water Withdrawal
A8: GRI 303-3 SASB EM-MM-140a.1 | B8: Global AEM | C8: Laronde | D8: Goldex | E8: Kittila | F8: Pinos Altos | G8: La India | H8: Meadowbank | I8: Meliadine
A9: Total Freshwater Withdrawal | B9: 9532210.4 | C9: 1130409.5 | D9: 1833148 | E9: 1880314 | F9: 1164981 | G9: 918899.1 | H9: 2280839 | I9: 323619.81
A10: Surface water (m³) | B10: 8154295.9 | C10: =SUM(C11:C12) -> 1128129 | D10: =SUM(D11:D12) -> 1821849 | E10: =SUM(E11:E12) -> 1819860 | F10: =SUM(F11:F12) -> 397568 | G10: =SUM(G11:G12) -> 382431.1 | H10: =SUM(H11:H12) -> 2280839 | I10: =SUM(I11:I12) -> 323619.81
A11: Pumped from open water bodies | B11: =SUM(C11:I11) -> 7374296.8 | C11: 1128129 | D11: 1821849 | E11: 1819860 | F11: - | G11: - | H11: 2280839 | I11: 323619.81
A12: Used from rain and snow melt | B12: =SUM(C12:I12) -> 779999.1 | C12: - | D12: - | E12: - | F12: 397568 | G12: 382431.1 | H12: - | I12: -
A13: Groundwater (m³) | B13: 1366615.5 | C13: 2280.5 | D13: - | E13: 60454 | F13: 767413 | G13: 536468 | H13: - | I13: -
A14: Third-party water (m³) | B14: 11299 | C14: - | D14: 11299 | E14: - | F14: - | G14: - | H14: - | I14: -
A15: Water Withdrawn Intensity | B15: =B9/'Materials, Tailings & Waste '!B9 -> 0.48720213 | C15: =C9/'Materials, Tailings & Waste '!C9 -> 0.38623307 | D15: =D9/'Materials, Tailings & Waste '!D9 -> 0.65833449 | E15: =E9/'Materials, Tailings & Waste '!E9 -> 1.1819171 | F15: =F9/'Materials, Tailings & Waste '!F9 -> 0.37903321 | G15: =G9/'Materials, Tailings & Waste '!G9 -> 0.17009043 | H15: =H9/'Materials, Tailings & Waste '!H9 -> 0.82930372 | I15: =I9/'Materials, Tailings & Waste '!I9 -> 0.3121495
A16: Percentage Water Withdrawn from Areas with High or Extremely High Baseline Water Stress | B16: =G9/B9 -> 0.096399372 | C16: - | D16: - | E16: - | F16: - | G16: 1 | H16: - | I16: -
A18: Water Consumption
A19: GRI 303-5 SASB EM-MM-140a.1 | B19: Global AEM | C19: Laronde | D19: Goldex | E19: Kittila | F19: Pinos Altos | G19: La India | H19: Meadowbank | I19: Meliadine
A20: Total Water Used (m³) | B20: 24950028 | C20: 5375597.7 | D20: 5408396 | E20: 5584424 | F20: 4424567 | G20: 944149.1 | H20: 2889274 | I20: 1407022
A21: Freshwater recycled (m³) | B21: 15417817 | C21: 4245188.2 | D21: 3575248 | E21: 3704110 | F21: 3259586 | G21: 25250 | H21: 608435 | I21: 1083402
A22: Fresh water recycled % | B22: 0.6179479 | C22: 0.78971464 | D22: 0.66105514 | E22: 0.66329312 | F22: 0.73670169 | G22: 0.026743657 | H22: 0.21058404 | I22: 0.77
A24: Water Discharge
A25: GRI 303-4, 306-1,306-5 | B25: Global AEM | C25: Laronde | D25: Goldex | E25: Kittila | F25: Pinos Altos | G25: La India | H25: Meadowbank | I25: Meliadine
A26: Water Discharged to Fresh Water Bodies (m³) | B26: 17407896 | C26: 4179232 | D26: 987301.1 | E26: 3800264 | F26: 515821 | G26: - | H26: 7589601 | I26: 335676.81
A27: Treatment Method | C27: Chemical Biological | D27: Passive water treatment | E27: Neutralization Sedimentation | F27: Activated sludge | G27: - | H27: -No treatment for East Dike Discharge (MBK) -Water Treatment Plan for some of the water discharged at Whale Tail | I27: Actiflow for TSS and Saline water treatment plant
A28: Destination | C28: Dormenan Creek | D28: Small creek | E28: River Seurujoki | F28: La Bateria and Concheño Stream | G28: - | H28: Second Portage Lake 39 700 000 m3 Whale Tail South 6,924,848m3 Mammoth Lake 6,290,000m3 Tundra in the Watershed of Nemo Lake 8,360,000m3 | I28: Meliadine Lake
A29: Water bodies and related habitats significantly affected by discharge | C29: Yes | D29: No | E29: Yes | F29: No | G29: - | H29: Yes | I29: No
A30: Water bodies and related habitats designated as protected area | C30: No | D30: No | E30: No | F30: No | G30: No | H30: No | I30: No
A31: Water bodies and related habitats identified as having high biodiversity value | C31: No | D31: No | E31: No | F31: No | G31: No | H31: No | I31: No

Sheet Materials, Tailings & Waste 
A7: Production
A8: GRI 301-1 SASB EM-MM-000.A | B8: Global AEM | C8: Laronde | D8: Goldex | E8: Kittila | F8: Pinos Altos | G8: La India | H8: Meadowbank | I8: Meliadine
A9: Total Ore processed (tonnes) | B9: 19565207 | C9: 2926754.8 | D9: 2784523.7 | E9: 1590901.7 | F9: 3073559.2 | G9: 5402415.1 | H9: 2750306 | I9: 1036746.2
A10: Total Gold (Oz) | B10: 1447551 | C10: 402989 | D10: 140884.2 | E10: 186100.52 | F10: 203504 | G10: 82190.091 | H10: 193489 | I10: 238393.97
A11: Total Silver (thousands of Oz) | B11: 3889 | C11: 896 | D11: 2 | E11: 13 | F11: 2741 | G11: 133 | H11: 86 | I11: 18
A12: Mill Zinc (t) | B12: 13161 | C12: 13161
A13: Mill Copper (t) | B13: 3397 | C13: 3397
A15: Total Waste Generated (Mineral and Non-Mineral Waste)
A16: GRI 306-2 SASB EM-MM-150a.1 | B16: Global AEM | C16: Laronde | D16: Goldex | E16: Kittila | F16: Pinos Altos | G16: La India | H16: Meadowbank | I16: Meliadine
A17: Total Non-Hazardous Waste Generated (tonnes) | B17: =B31+B41+B51 -> 31453321 | C17: =C31+C41+C51 -> 66466.667 | D17: =D31+D41+D51 -> 2896097 | E17: =E31+E41+E51 -> 1875738.9 | F17: =F31+F41+F51 -> 11180406 | G17: =G31+G41+G51 -> 8282763.4 | H17: =H31+H41+H51 -> 3398914.1 | I17: =I31+I41+I51 -> 1682057.6
A18: Total Hazardous Waste Generated (tonnes) | B18: =B26+B38+B63 -> 23660844 | C18: =C26+C38+C63 -> 3656445.5 | D18: =D26+D38+D63 -> 225.148 | E18: =E26+E38+E63 -> 1812825.2 | F18: =F26+F38+F63 -> 2071457.6 | G18: =G26+G38+G63 -> 450.69 | H18: =H26+H38+H63 -> 16118634 | I18: =I26+I38+I63 -> 806.7
A19: Total Waste Generated (tonnes) | B19: =SUM(B17:B18) -> 55114165 | C19: =SUM(C17:C18) -> 3722912.2 | D19: =SUM(D17:D18) -> 2896322.2 | E19: =SUM(E17:E18) -> 3688564 | F19: =SUM(F17:F18) -> 13251864 | G19: =SUM(G17:G18) -> 8283214.1 | H19: =SUM(H17:H18) -> 19517548 | I19: =SUM(I17:I18) -> 1682864.3
A20: Total Waste Recycled (tonnes) | B20: =SUM(B27:B29,B32:B34,B39,B42,B61) -> 10427947 | C20: =SUM(C27:C29,C32:C34,C39,C42,C61) -> 1807031.3 | D20: =SUM(D27:D29,D32:D34,D39,D42,D61) -> 1507471.8 | E20: =SUM(E27:E29,E32:E34,E39,E42,E61) -> 1844828.1 | F20: =SUM(F27:F29,F32:F34,F39,F42,F61) -> 1355635.7 | G20: =SUM(G27:G29,G32:G34,G39,G42,G61) -> 228.36 | H20: =SUM(H27:H29,H32:H34,H39,H42,H61) -> 3098561.2 | I20: =SUM(I27:I29,I32:I34,I39,I42,I61) -> 814190.58
A21: Percentage (%) Waste Recycled (tonnes) | B21: =B20/B19 -> 0.1892063 | C21: =C20/C19 -> 0.48538112 | D21: =D20/D19 -> 0.52047794 | E21: =E20/E19 -> 0.50014804 | F21: =F20/F19 -> 0.10229774 | G21: =G20/G19 -> 2.7569009e-05 | H21: =H20/H19 -> 0.15875771 | I21: =I20/I19 -> 0.48381238
A23: Mined Material
A24: GRI 306-2 | B24: Global AEM | C24: Laronde | D24: Goldex | E24: Kittila | F24: Pinos Altos | G24: La India | H24: Meadowbank | I24: Meliadine
A25: Total Waste Rock Mined (tonnes) | B25: =SUM(C25:I25) -> 39937032 | C25: 838268 | D25: 187683 | E25: =E26+E31 -> 2054581.5 | F25: 11179033 | G25: 8282481 | H25: 16754769 | I25: 640216.08
A26: Total Potentially Hazardous Waste Rock Mined (tonnes) | B26: =SUM(C26:I26) -> 14818875 | C26: 774902 | D26: 0 | E26: =SUM(E27:E30) -> 678881.46 | F26: 0 | G26: 0 | H26: 13365092 | I26: 0
A27: Waste rock returned underground as backfill or in pits (tonnes) | B27: =SUM(C27:I27) -> 1724786.6 | C27: 330828 | D27: 0 | E27: 267217.61 | F27: 0 | G27: 0 | H27: 1126741 | I27: 0
A28: Waste rock used in tailings dam construction (tonnes) | B28: =SUM(C28:I28) -> 569999.7 | C28: 436354 | D28: 0 | E28: 104221.7 | F28: 0 | G28: 0 | H28: 29424 | I28: 0
A29: Waste rock used in other construction (tonnes) | B29: =SUM(C29:I29) -> 70013 | C29: 7720 | D29: 0 | E29: 0 | F29: 0 | G29: 0 | H29: 62293 | I29: 0
A30: Waste rock placed on surface or removed from waste rock piles (tonnes) | B30: =SUM(C30:I30) -> 12454076 | D30: 0 | E30: 307442.15 | F30: 0 | G30: 0 | H30: 12146634 | I30: 0
A31: Total Non-Hazardous Waste Rock Mined (tonnes) | B31: =SUM(C31:I31) -> 25118156 | C31: =C32 -> 63366 | D31: 187683 | E31: =SUM(E32:E35) -> 1375700 | F31: 11179033 | G31: 8282481 | H31: 3389677 | I31: 640216.08
A32: Waste rock returned underground as backfill or in pits (tonnes) | B32: =SUM(C32:I32) -> 1031237.7 | C32: 63366 | D32: 72098 | E32: 289485.74 | F32: 244334 | G32: 0 | H32: 357623 | I32: 4331
A33: Waste rock used in tailings dam construction (tonnes) | B33: =SUM(C33:I33) -> 607513 | C33: 0 | D33: 27530 | E33: 422659 | F33: 70133 | G33: 0 | H33: 87191
A34: Waste rock used in other construction (tonnes) | B34: =SUM(C34:I34) -> 2633574.3 | C34: 0 | D34: 81791 | E34: 261205.2 | F34: 221390 | G34: 0 | H34: 1433303 | I34: 635885.08
A35: Waste rock placed on surface or removed from waste rock piles (tonnes) | B35: =SUM(C35:I35) -> 20845831 | D35: 6264 | E35: 402350.1 | F35: 10643176 | G35: 8282481 | H35: 1511560 | I35: 0
A36: Percentage (%) Waste Rock Recycled | B36: =(SUM(B27:B29,B32:B34))/B25 -> 0.16618973 | C36: =(SUM(C27:C29,C32:C34))/C25 -> 1 | D36: =(SUM(D27:D29,D32:D34))/D25 -> 0.96662457 | E36: =(SUM(E27:E29,E32:E34))/E25 -> 0.65453196 | F36: =(SUM(F27:F29,F32:F34))/F25 -> 0.04793411 | G36: =(SUM(G27:G29,G32:G34))/G25 -> 0 | H36: =(SUM(H27:H29,H32:H34))/H25 -> 0.18481753 | I36: =(SUM(I27:I29,I32:I34))/I25 -> 1
A37: Total Mill tailings produced (tonnes) | B37: =SUM(C37:I37) -> 13076790 | C37: 2881057.1 | D37: 2706571 | E37: 1631231 | F37: =F38+F41 -> 2070877 | G37: 0 | H37: 2750306 | I37: 1036748
A38: Total Potentially Hazardous Mill tailings produced (tonnes) | B38: =SUM(C38:I38) -> 8835944.1 | C38: 2881057.1 | D38: 0 | E38: 1133704 | F38: 2070877 | G38: 0 | H38: 2750306 | I38: 0
A39: Mill tailings returned underground as backfill (tonnes) | B39: =SUM(C39:I39) -> 1785569 | C39: 966632 | D39: 0 | E39: 0 | F39: 818937 | G39: 0 | H39: 0 | I39: 0
A40: Mill tailings placed in surface tailings containment (tonnes) | B40: =SUM(C40:I40) -> 7050375.1 | C40: 1914425.1 | D40: 0 | E40: 1133704 | F40: 1251940 | G40: 0 | H40: 2750306 | I40: 0
A41: Total Non-Hazardous Mill tailings produced (tonnes) | B41: 6311723 | C41: 0 | D41: 2706571 | E41: 497527 | F41: 0 | G41: 0 | H41: 0 | I41: 1036748
A42: Mill tailings returned underground as backfill (tonnes) | B42: =SUM(C42:I42) -> 1995970 | C42: 0 | D42: 1324510 | E42: 497527 | F42: 0 | G42: 0 | H42: 0 | I42: 173933
A43: Mill tailings placed in surface tailings containment (tonnes) | B43: =SUM(C43:I43) -> 2244876 | C43: 0 | D43: 1382061 | E43: 0 | F43: 0 | G43: 0 | H43: 0 | I43: 862815
A44: Percentage (%) Mill Tailings recycled | B44: =SUM(B42,B39)/B37 -> 0.28917945 | C44: =SUM(C42,C39)/C37 -> 0.33551296 | D44: =SUM(D42,D39)/D37 -> 0.48936828 | E44: =SUM(E42,E39)/E37 -> 0.30500095 | F44: =SUM(F42,F39)/F37 -> 0.3954542 | G44: 0 | H44: =SUM(H42,H39)/H37 -> 0 | I44: =SUM(I42,I39)/I37 -> 0.16776787
A45: Total Mined Material | B45: =B37+B25 -> 53013822 | C45: =C37+C25 -> 3719325.1 | D45: =D37+D25 -> 2894254 | E45: =E37+E25 -> 3685812.5 | F45: =F37+F25 -> 13249910 | G45: =G37+G25 -> 8282481 | H45: =H37+H25 -> 19505075 | I45: =I37+I25 -> 1676964.1
A46: Total Hazardous Mined Material | B46: =B26+B38 -> 23654820 | C46: =C26+C38 -> 3655959.1 | D46: =D26+D38 -> 0 | E46: =E26+E38 -> 1812585.5 | F46: =F26+F38 -> 2070877 | G46: =G26+G38 -> 0 | H46: =H26+H38 -> 16115398 | I46: =I26+I38 -> 0
A47: Total Non-Hazardous Mine Material | B47: =B31+B41 -> 31429879 | C47: =C31+C41 -> 63366 | D47: =D31+D41 -> 2894254 | E47: =E31+E41 -> 1873227 | F47: =F31+F41 -> 11179033 | G47: =G31+G41 -> 8282481 | H47: =H31+H41 -> 3389677 | I47: =I31+I41 -> 1676964.1
A49: Domestic Waste & Non-Mineral Hazardous Waste
...

Sheet Environmental Stewardship
A7: Operational sites owned, leased, managed in, or adjacent to, protected areas and areas of high biodiversity value outside protected area
A8: GRI 304-1 SASB EM-MM-160a.3 | C8: Laronde | D8: Goldex | E8: Kittila | F8: Pinos Altos | G8: La India1 | H8: Meadowbank | I8: Meliadine
A9: Geographic Location | C9: Quebec, Canada | D9: Quebec, Canada | E9: Lapland, Finland | F9: Chihuahua State, Mexico | G9: Sonora State, Mexico | H9: Nunavut, Canada | I9: Nunavut, Canada
A10: Size of operational site (ha) | C10: 785 | D10: 519 | E10: 1147 | F10: 7206 | G10: 4512 | H10: 3150.32 | I10: 880
A11: Total Mine area physically disturbed by mine activity (ha) | C11: 706 | D11: 330 | E11: 1147 | F11: 663.13 | G11: 312 | H11: 3150.32 | I11: 453
A12: Position in relation to protected area | C12: - | D12: - | E12: Adjacent | F12: In the area | G12: - | H12: - | I12: -
A13: Ecosystem of Protected or High Biodiversity Areas | C13: - | D13: - | E13: Terrestrial | F13: Terrestrial | G13: - | H13: - | I13: -
A14: Listing of Protected Status | C14: - | D14: - | E14: National legislation | F14: National legislation | G14: - | H14: - | I14: -
A15: 1 23 October 2020: The value for size of operation site (ha) was restated from 312 to 4,512. The total mine areas physically disturbed by the mine was restated from 4,512 to 312.
A17: Habitats protected or restored
A18: GRI 304-3 | C18: Laronde | D18: Goldex | E18: Kittila | F18: Pinos Altos | G18: La India | H18: Meadowbank | I18: Meliadine
A19: Size of protected land (ha) | C19: - | D19: - | E19: 8 | F19: 300 | H19: - | I19: -
A20: Size of land designated for restoration (ha) | C20: - | D20: - | E20: - | F20: 663.13 | H20: 3150 | I20: 418
A21: Size of land successfully restored (ha) | C21: - | D21: - | E21: - | F21: 32.9 | G21: 6 | H21: - | I21: -
A22: Status of restoration | C22: - | D22: - | E22: - | F22: In progress | G22: In progress | H22: In progress | I22: Not started
A23: Do partnerships exist with third parties to protect or restore distinct habitat? | C23: - | D23: - | E23: Yes | F23: Yes | G23: No | H23: No | I23: No
A24: Does successful restoration require approval by independent external professionals? | C24: - | D24: - | E24: Yes | F24: Yes | G24: No | H24: N/A | I24: N/A
A26: IUCN Red List species and national conservation list species with habitats in areas affected by operations
A27: GRI 304-4 SASB EM-MM-160a.3 | C27: Laronde | D27: Goldex | E27: Kittila | F27: Pinos Altos | G27: La India | H27: Meadowbank | I27: Meliadine
A28: Total IUCN Red list species and national conservation list species | C28: 0 | D28: 0 | E28: 0 | F28: 0 | G28: 0 | H28: 28 | I28: 28
A29: Critically endangered | C29: - | D29: - | E29: - | F29: - | G29: - | H29: 0 | I29: 0
A30: Endangered | C30: - | D30: - | E30: - | F30: - | G30: - | H30: 0 | I30: 0
A31: Vulnerable | C31: - | D31: - | E31: - | F31: - | G31: - | H31: 0 | I31: 0
A32: Near Threatened | C32: - | D32: - | E32: - | F32: - | G32: - | H32: 0 | I32: 0
A33: Least Concerned | C33: - | D33: - | E33: - | F33: - | G33: - | H33: 27 | I33: 27
A34: Other | C34: - | D34: - | E34: - | F34: - | G34: - | H34: 1 | I34: 1
A36: Cyanide Management
B37: Global AEM | C37: Laronde | D37: Goldex | E37: Kittila | F37: Pinos Altos | G37: La India | H37: Meadowbank | I37: Meliadine
A38: Cyanide use (tonnes) | B38: =SUM(C38:I38) -> 9468.032 | C38: 195.032 | D38: N/A | E38: 435 | F38: 2324 | G38: 4432 | H38: 1092 | I38: 990
A39: Total Cyanide releases off site that requires response or remediation | B39: 0 | C39: 0 | D39: N/A | E39: 0 | F39: No | G39: No | H39: 0 | I39: 0
A40: Incidents with adverse health effects | B40: 0 | C40: 0 | D40: N/A | E40: 0 | F40: No | G40: No | H40: 0 | I40: 0
A41: Incidents with adverse effects to the environment | B41: 0 | C41: 0 | D41: N/A | E41: 0 | F41: No | G41: No | H41: 0 | I41: 0
A42: Incidents that require reporting under applicable regulations | B42: 4 | C42: 4 | D42: N/A | E42: 0 | F42: No | G42: No | H42: 0 | I42: 0
A43: Exceedances of applicable limits of cyanide code | B43: 0 | C43: N/A | D43: N/A | E43: 0 | F43: No | G43: No | H43: 0 | I43: 0
A44: Cyanide related wildlife fatalities | B44: 0 | C44: 0 | D44: N/A | E44: 0 | F44: No | G44: No | H44: 0 | I44: 0

Sheet Communities & Indigenous People
A7: Operations taking place in or near indigenous territory
A8: GRI MM05 SASB EM-MM-210a.2 | C8: Laronde | D8: Goldex | E8: Kittila | F8: Pinos Altos | G8: La India | H8: Meadowbank | I8: Meliadine
A9: Is the operation adjacent¹ or on indigenous peoples' territory? | C9: Yes | D9: Yes | E9: Yes | F9: No | G9: No | H9: Yes | I9: Yes
A10: Do formal agreements exist with indigenous peoples? | C10: No | D10: No | E10: Yes | F10: No | G10: No | H10: Yes | I10: Yes
A11: ¹ Adjacent refers to land physically next to, or influenced by, the operation site
A13: Operations with local community engagement, impact assessments, and development programs
A14: GRI 413-1 | B14: Global AEM² | C14: Laronde | D14: Goldex | E14: Kittila | F14: Pinos Altos | G14: La India | H14: Meadowbank | I14: Meliadine
A15: Has the mine been subject to a social impact assessment? | B15: =6/7 -> 0.85714286 | C15: No | D15: Yes | E15: Yes | F15: Yes | G15: Yes | H15: Yes | I15: Yes
A16: Are the results of environmental and social impact assessments publicly disclosed? | B16: 0.86 | C16: No | D16: Yes | E16: Yes | F16: Yes | G16: Yes | H16: Yes | I16: Yes
A17: Are local community investment plans based on local community needs? | B17: 1 | C17: Yes | D17: Yes | E17: Yes | F17: Yes | G17: Yes | H17: Yes | I17: Yes
A18: Are stakeholder engagement plans based on stakeholder mapping? | B18: 1 | C18: Yes | D18: Yes | E18: Yes | F18: Yes | G18: Yes | H18: Yes | I18: Yes
A19: Are there local community consultation committees? | B19: 1 | C19: Yes | D19: Yes | E19: Yes | F19: Yes | G19: Yes | H19: Yes | I19: Yes
A20: Are there processes to include vulnerable¹ groups in community consultation committees or other forms of community engagement? | B20: 1 | C20: Yes | D20: Yes | E20: Yes | F20: Yes | G20: Yes | H20: Yes | I20: Yes
A21: Is there a formal local community grievance process? | B21: 1 | C21: Yes | D21: Yes | E21: Yes | F21: Yes | G21: Yes | H21: Yes | I21: Yes
A22: ¹ Vulnerable groups are defined as groups at higher risk of being subjected to social, economic or environmental impacts of our organization’s operation. Vulnerable groups vary by operation and can include youth, elders, women, people with disabilities, Indigenous Peoples and ethnic minorities.
A23: 2 4 November 2020 : The values were restated to correctly reflect information reported for each operation
A25: Operations with local community engagement, impact assessments, and development programs
A26: GRI 413-2 | C26: Laronde | D26: Goldex | E26: Kittila | F26: Pinos Altos | G26: La India | H26: Meadowbank | I26: Meliadine
A27: Are there actual or potential negative social impacts on local communities? | C27: Potential impacts | D27: Potential impacts | E27: No impacts | F27: No impacts | G27: No impacts | H27: Potential impacts | I27: Potential impacts
A28: Are there actual or potential negative economic impacts on local communities? | C28: No impacts | D28: No impacts | E28: No impacts | F28: No impacts | G28: No impacts | H28: No impacts | I28: No impacts
A29: Are there actual or potential negative impacts on the local communities' environmental well-being? | C29: Actual impacts | D29: Actual impacts | E29: Actual impacts¹ | F29: No impacts | G29: No impacts | H29: Potential impacts | I29: Potential impacts
A30: ¹ Discharging of process and mine drainage water from the site to the nearby river, as per environmental permit. The nearby river is used for recreational fishing.
A32: Grievances mechanisms & outcomes
A33: GRI 413-2 | B33: Global AEM | C33: Laronde | D33: Goldex | E33: Kittila | F33: Pinos Altos | G33: La India | H33: Meadowbank² | I33: Meliadine²
A34: Total number of community grievances or complaints¹ | B34: =SUM(C34:I34) -> 48 | C34: 19 | D34: 7 | E34: 2 | F34: 1 | G34: 2 | H34: 6.5 | I34: 10.5
A35: Environmental | B35: =SUM(C35:I35) -> 5 | C35: 0 | D35: 0 | E35: 0 | F35: 0 | G35: 1 | H35: 0 | I35: 4
A36: Health & Safety | B36: =SUM(C36:I36) -> 6 | C36: 3 | D36: 0 | E36: 2 | F36: 0 | G36: 0 | H36: 0 | I36: 1
A37: Social and Communities | B37: =SUM(C37:I37) -> 1 | C37: 0 | D37: 0 | E37: 0 | F37: 0 | G37: 0 | H37: 0.5 | I37: 0.5
A38: Economic opportunities (e.g. employment & procurement) | B38: =SUM(C38:I38) -> 4 | C38: 0 | D38: 0 | E38: 0 | F38: 1 | G38: 0 | H38: 1 | I38: 2
A39: Indigenous rights | B39: =SUM(C39:I39) -> 0 | C39: 0 | D39: 0 | E39: 0 | F39: 0 | G39: 0 | H39: 0 | I39: 0
A40: Land and resource use | B40: =SUM(C40:I40) -> 6 | C40: 0 | D40: 0 | E40: 0 | F40: 0 | G40: 0 | H40: 4 | I40: 2
A41: Mining practices and activities | B41: =SUM(C41:I41) -> 26 | C41: 16 | D41: 7 | E41: 0 | F41: 0 | G41: 1 | H41: 1 | I41: 1
A42: Number of grievances or complaints investigated | B42: =SUM(C42:I42) -> 42 | C42: 19 | D42: 7 | E42: 2 | F42: 1 | G42: 0 | H42: 5 | I42: 8
A43: Number of remediation plans implemented as a result of an investigation | B43: =SUM(C43:I43) -> 29 | C43: 11 | D43: 7 | E43: 2 | F43: 1 | G43: 0 | H43: 4 | I43: 4
A44: Number of grievances or complaints resolved, completed or withdrawn at the end of the year | B44: =SUM(C44:I44) -> 37 | C44: 15 | D44: 5 | E44: 2 | F44: 1 | G44: 0 | H44: 6 | I44: 8
A45: ¹ Specific issues of concern to community members that requires a response from the company and potentially further action
A46: ² Grievances made at a regional level in Nunavut are split with a value of 0.5 at each site
